Traceback (most recent call last):
  File "C:\Users\kaede\anaconda3\envs\eiyl_notebook\lib\site-packages\jupyter_cache\executors\utils.py", line 56, in single_nb_execution
    record_timing=False,
  File "C:\Users\kaede\anaconda3\envs\eiyl_notebook\lib\site-packages\nbclient\client.py", line 1112, in execute
    return NotebookClient(nb=nb, resources=resources, km=km, **kwargs).execute()
  File "C:\Users\kaede\anaconda3\envs\eiyl_notebook\lib\site-packages\nbclient\util.py", line 74, in wrapped
    return just_run(coro(*args, **kwargs))
  File "C:\Users\kaede\anaconda3\envs\eiyl_notebook\lib\site-packages\nbclient\util.py", line 53, in just_run
    return loop.run_until_complete(coro)
  File "C:\Users\kaede\anaconda3\envs\eiyl_notebook\lib\asyncio\base_events.py", line 587, in run_until_complete
    return future.result()
  File "C:\Users\kaede\anaconda3\envs\eiyl_notebook\lib\site-packages\nbclient\client.py", line 554, in async_execute
    cell, index, execution_count=self.code_cells_executed + 1
  File "C:\Users\kaede\anaconda3\envs\eiyl_notebook\lib\site-packages\nbclient\client.py", line 857, in async_execute_cell
    self._check_raise_for_error(cell, exec_reply)
  File "C:\Users\kaede\anaconda3\envs\eiyl_notebook\lib\site-packages\nbclient\client.py", line 760, in _check_raise_for_error
    raise CellExecutionError.from_cell_and_msg(cell, exec_reply_content)
nbclient.exceptions.CellExecutionError: An error occurred while executing the following cell:
------------------
between_15_20 <- filter(temperature_data, 
                        between(ext_temp, 15, 20))
count(between_15_20)$n / count(temperature_data)$n
------------------

Error in between(ext_temp, 15, 20): object 'ext_temp' not found
Traceback:

1. filter(temperature_data, between(ext_temp, 15, 20))
2. filter.tbl_df(temperature_data, between(ext_temp, 15, 20))
3. filter_impl(.data, quo)
4. between(ext_temp, 15, 20)
ERROR: Error in between(ext_temp, 15, 20): object 'ext_temp' not found


